<?xml version="1.0" encoding="utf-8"?>
<!-- This URDF was automatically created by SolidWorks to URDF Exporter! Originally created by Stephen Brawner (brawner@gmail.com) 
     Commit Version: 1.5.1-0-g916b5db  Build Version: 1.5.7152.31018
     For more information, please see http://wiki.ros.org/sw_urdf_exporter -->
<robot
  name="lide">
  <link
    name="base_link">
    <inertial>
      <origin
        xyz="-0.123905080916601 0.0849038994359379 0.0505995438981258"
        rpy="0 0 0" />
      <mass
        value="2.91428056653758" />
      <inertia
        ixx="0.00617409122645341"
        ixy="-7.15450905274627E-07"
        ixz="-1.26542370052897E-05"
        iyy="0.00553452148968598"
        iyz="-3.51329121715535E-07"
        izz="0.0110503775267064" />
    </inertial>
    <visual>
      <origin
        xyz="0 0 0"
        rpy="0 0 0" />
      <geometry>
        <mesh
          filename="package://lide/meshes/base_link.STL" />
      </geometry>
      <material
        name="">
        <color
          rgba="0.752941176470588 0.752941176470588 0.752941176470588 1" />
      </material>
    </visual>
    <collision>
      <origin
        xyz="0 0 0"
        rpy="0 0 0" />
      <geometry>
        <mesh
          filename="package://lide/meshes/base_link.STL" />
      </geometry>
    </collision>
  </link>
  <link
    name="LFS">
    <inertial>
      <origin
        xyz="0.0455604268709419 -0.0546933148939941 0.00297622851896683"
        rpy="0 0 0" />
      <mass
        value="0.0727928435161986" />
      <inertia
        ixx="2.20927876796312E-05"
        ixy="-1.64845302056394E-08"
        ixz="-1.56454773175215E-07"
        iyy="1.62632133784213E-05"
        iyz="2.9641187651118E-09"
        izz="1.80843397531752E-05" />
    </inertial>
    <visual>
      <origin
        xyz="0 0 0"
        rpy="0 0 0" />
      <geometry>
        <mesh
          filename="package://lide/meshes/LFS.STL" />
      </geometry>
      <material
        name="">
        <color
          rgba="0.752941176470588 0.752941176470588 0.752941176470588 1" />
      </material>
    </visual>
    <collision>
      <origin
        xyz="0 0 0"
        rpy="0 0 0" />
      <geometry>
        <mesh
          filename="package://lide/meshes/LFS.STL" />
      </geometry>
    </collision>
  </link>
  <joint
    name="LFS"
    type="prismatic">
    <origin
      xyz="-0.0540436140506676 0.182406433684605 0.0265000000000001"
      rpy="1.5707963267949 0 1.5707963267949" />
    <parent
      link="base_link" />
    <child
      link="LFS" />
    <axis
      xyz="0 1 0" />
    <limit
      lower="0"
      upper="0"
      effort="0"
      velocity="0" />
  </joint>
  <link
    name="LFW">
    <inertial>
      <origin
        xyz="0.015 0 3.46944695195361E-18"
        rpy="0 0 0" />
      <mass
        value="0.767080911081153" />
      <inertia
        ixx="0.00116426102407189"
        ixy="4.45758864315272E-22"
        ixz="-1.82994146746971E-20"
        iyy="0.000639661580367031"
        iyz="-1.35525271560688E-20"
        izz="0.000639661580367032" />
    </inertial>
    <visual>
      <origin
        xyz="0 0 0"
        rpy="0 0 0" />
      <geometry>
        <mesh
          filename="package://lide/meshes/LFW.STL" />
      </geometry>
      <material
        name="">
        <color
          rgba="0.898039215686275 0.917647058823529 0.929411764705882 1" />
      </material>
    </visual>
    <collision>
      <origin
        xyz="0 0 0"
        rpy="0 0 0" />
      <geometry>
        <mesh
          filename="package://lide/meshes/LFW.STL" />
      </geometry>
    </collision>
  </link>
  <joint
    name="LFW"
    type="continuous">
    <origin
      xyz="0.0633463599631527 -0.0698007864376269 0.0150436140506676"
      rpy="-1.62639053095063 0 0" />
    <parent
      link="LFS" />
    <child
      link="LFW" />
    <axis
      xyz="1 0 0" />
    <limit
      effort="3.1"
      velocity="7" />
  </joint>
  <link
    name="RFS">
    <inertial>
      <origin
        xyz="-0.0191828308457407 -0.054724936878019 0.0520056318885905"
        rpy="0 0 0" />
      <mass
        value="0.0727928435161986" />
      <inertia
        ixx="2.20927876796313E-05"
        ixy="-1.6484530205632E-08"
        ixz="1.56454773175213E-07"
        iyy="1.62632133784213E-05"
        iyz="-2.96411876510424E-09"
        izz="1.80843397531752E-05" />
    </inertial>
    <visual>
      <origin
        xyz="0 0 0"
        rpy="0 0 0" />
      <geometry>
        <mesh
          filename="package://lide/meshes/RFS.STL" />
      </geometry>
      <material
        name="">
        <color
          rgba="0.752941176470588 0.752941176470588 0.752941176470588 1" />
      </material>
    </visual>
    <collision>
      <origin
        xyz="0 0 0"
        rpy="0 0 0" />
      <geometry>
        <mesh
          filename="package://lide/meshes/RFS.STL" />
      </geometry>
    </collision>
  </link>
  <joint
    name="RFS"
    type="prismatic">
    <origin
      xyz="-0.103073017420291 -0.0427840297098062 0.0265"
      rpy="1.5707963267949 0 1.5707963267949" />
    <parent
      link="base_link" />
    <child
      link="RFS" />
    <axis
      xyz="0 1 0" />
    <limit
      lower="0"
      upper="0"
      effort="0"
      velocity="0" />
  </joint>
  <link
    name="RFW">
    <inertial>
      <origin
        xyz="-0.015 0 0"
        rpy="0 0 0" />
      <mass
        value="0.767080911081152" />
      <inertia
        ixx="0.00116426102407189"
        ixy="-1.2315168370675E-36"
        ixz="4.60638074444741E-39"
        iyy="0.000639661580367031"
        iyz="8.00462841683581E-39"
        izz="0.000639661580367031" />
    </inertial>
    <visual>
      <origin
        xyz="0 0 0"
        rpy="0 0 0" />
      <geometry>
        <mesh
          filename="package://lide/meshes/RFW.STL" />
      </geometry>
      <material
        name="">
        <color
          rgba="0.898039215686275 0.917647058823529 0.929411764705882 1" />
      </material>
    </visual>
    <collision>
      <origin
        xyz="0 0 0"
        rpy="0 0 0" />
      <geometry>
        <mesh
          filename="package://lide/meshes/RFW.STL" />
      </geometry>
    </collision>
  </link>
  <joint
    name="RFW"
    type="continuous">
    <origin
      xyz="-0.0369687639379516 -0.0697992135623731 0.0640730174202912"
      rpy="0 0 0" />
    <parent
      link="RFS" />
    <child
      link="RFW" />
    <axis
      xyz="1 0 0" />
    <limit
      effort="3.1"
      velocity="7" />
  </joint>
  <link
    name="LBS">
    <inertial>
      <origin
        xyz="-4.7988246709707E-10 -0.0360357103914947 -1.16815018769145E-09"
        rpy="0 0 0" />
      <mass
        value="0.083535872081433" />
      <inertia
        ixx="7.72968060896301E-05"
        ixy="-8.60478073467301E-13"
        ixz="1.40586674043926E-13"
        iyy="5.13820931926883E-05"
        iyz="-5.06559896269576E-12"
        izz="7.73952626484254E-05" />
    </inertial>
    <visual>
      <origin
        xyz="0 0 0"
        rpy="0 0 0" />
      <geometry>
        <mesh
          filename="package://lide/meshes/LBS.STL" />
      </geometry>
      <material
        name="">
        <color
          rgba="0.898039215686275 0.917647058823529 0.929411764705882 1" />
      </material>
    </visual>
    <collision>
      <origin
        xyz="0 0 0"
        rpy="0 0 0" />
      <geometry>
        <mesh
          filename="package://lide/meshes/LBS.STL" />
      </geometry>
    </collision>
  </link>
  <joint
    name="LBS"
    type="prismatic">
    <origin
      xyz="-0.201999999999999 0.228002793647758 0"
      rpy="1.5707963267949 0 1.5707963267949" />
    <parent
      link="base_link" />
    <child
      link="LBS" />
    <axis
      xyz="0 1 0" />
    <limit
      lower="0"
      upper="0"
      effort="0"
      velocity="0" />
  </joint>
  <link
    name="LBW">
    <inertial>
      <origin
        xyz="0 5.55111512312578E-17 0"
        rpy="0 0 0" />
      <mass
        value="0.300793834102321" />
      <inertia
        ixx="0.000108556494727528"
        ixy="1.72053926402305E-55"
        ixz="1.86282862584916E-40"
        iyy="0.000109910066980988"
        iyz="-7.74861998833051E-40"
        izz="0.000108556494727528" />
    </inertial>
    <visual>
      <origin
        xyz="0 0 0"
        rpy="0 0 0" />
      <geometry>
        <mesh
          filename="package://lide/meshes/LBW.STL" />
      </geometry>
      <material
        name="">
        <color
          rgba="0.898039215686275 0.917647058823529 0.929411764705882 1" />
      </material>
    </visual>
    <collision>
      <origin
        xyz="0 0 0"
        rpy="0 0 0" />
      <geometry>
        <mesh
          filename="package://lide/meshes/LBW.STL" />
      </geometry>
    </collision>
  </link>
  <joint
    name="LBW"
    type="revolute">
    <origin
      xyz="0 -0.0683 0"
      rpy="3.1416 0 1.5708" />
    <parent
      link="LBS" />
    <child
      link="LBW" />
    <axis
      xyz="0 1 0" />
    <limit
      lower="0"
      upper="0"
      effort="0"
      velocity="0" />
    <dynamics
      damping="0.001" />
  </joint>
  <link
    name="RBS">
    <inertial>
      <origin
        xyz="-4.79882529547115E-10 -0.0360357103914948 -1.16815021544703E-09"
        rpy="0 0 0" />
      <mass
        value="0.083535872081433" />
      <inertia
        ixx="7.72968060896302E-05"
        ixy="-8.6047810845422E-13"
        ixz="1.40586703451147E-13"
        iyy="5.13820931926882E-05"
        iyz="-5.06559895603098E-12"
        izz="7.73952626484253E-05" />
    </inertial>
    <visual>
      <origin
        xyz="0 0 0"
        rpy="0 0 0" />
      <geometry>
        <mesh
          filename="package://lide/meshes/RBS.STL" />
      </geometry>
      <material
        name="">
        <color
          rgba="0.898039215686275 0.917647058823529 0.929411764705882 1" />
      </material>
    </visual>
    <collision>
      <origin
        xyz="0 0 0"
        rpy="0 0 0" />
      <geometry>
        <mesh
          filename="package://lide/meshes/RBS.STL" />
      </geometry>
    </collision>
  </link>
  <joint
    name="RBS"
    type="prismatic">
    <origin
      xyz="-0.201999999999999 -0.0620027936477575 0"
      rpy="1.5707963267949 0 1.5707963267949" />
    <parent
      link="base_link" />
    <child
      link="RBS" />
    <axis
      xyz="0 1 0" />
    <limit
      lower="0"
      upper="0"
      effort="0"
      velocity="0" />
  </joint>
  <link
    name="RBW">
    <inertial>
      <origin
        xyz="6.93889390390723E-18 -6.93889390390723E-18 0"
        rpy="0 0 0" />
      <mass
        value="0.300793834102321" />
      <inertia
        ixx="0.000108556494727528"
        ixy="0"
        ixz="2.6460766815662E-40"
        iyy="0.000109910066980988"
        iyz="-7.74861998833051E-40"
        izz="0.000108556494727528" />
    </inertial>
    <visual>
      <origin
        xyz="0 0 0"
        rpy="0 0 0" />
      <geometry>
        <mesh
          filename="package://lide/meshes/RBW.STL" />
      </geometry>
      <material
        name="">
        <color
          rgba="0.898039215686275 0.917647058823529 0.929411764705882 1" />
      </material>
    </visual>
    <collision>
      <origin
        xyz="0 0 0"
        rpy="0 0 0" />
      <geometry>
        <mesh
          filename="package://lide/meshes/RBW.STL" />
      </geometry>
    </collision>
  </link>
  <joint
    name="RBW"
    type="revolute">
    <origin
      xyz="0 -0.0683 0"
      rpy="0 0 -1.5708" />
    <parent
      link="RBS" />
    <child
      link="RBW" />
    <axis
      xyz="0 1 0" />
    <limit
      lower="0"
      upper="0"
      effort="0"
      velocity="0" />
    <dynamics
      damping="0.001" />
  </joint>
  <link
    name="fcam">
    <inertial>
      <origin
        xyz="-0.0115544746517359 -2.64429642848896E-06 0.00129029302682179"
        rpy="0 0 0" />
      <mass
        value="0.0436119957238952" />
      <inertia
        ixx="2.35707061906175E-05"
        ixy="-1.01842273865773E-09"
        ixz="2.17585832536658E-08"
        iyy="4.29479050056035E-06"
        iyz="-8.8501811875969E-10"
        izz="2.21058153511886E-05" />
    </inertial>
    <visual>
      <origin
        xyz="0 0 0"
        rpy="0 0 0" />
      <geometry>
        <mesh
          filename="package://lide/meshes/fcam.STL" />
      </geometry>
      <material
        name="">
        <color
          rgba="0.792156862745098 0.819607843137255 0.933333333333333 1" />
      </material>
    </visual>
    <collision>
      <origin
        xyz="0 0 0"
        rpy="0 0 0" />
      <geometry>
        <mesh
          filename="package://lide/meshes/fcam.STL" />
      </geometry>
    </collision>
  </link>
  <joint
    name="fcam"
    type="fixed">
    <origin
      xyz="-0.0038823 0.083 0.12982"
      rpy="0 0.2618 0" />
    <parent
      link="base_link" />
    <child
      link="fcam" />
    <axis
      xyz="0 0 0" />
  </joint>
  <link
    name="bcam">
    <inertial>
      <origin
        xyz="-0.02010346452991 -2.6435490328991E-06 -0.00725869505663598"
        rpy="0 0 0" />
      <mass
        value="0.0436119949785286" />
      <inertia
        ixx="2.35707056099601E-05"
        ixy="-1.01834758005687E-09"
        ixz="2.17579332532698E-08"
        iyy="4.29479078276665E-06"
        iyz="-8.85484503961574E-10"
        izz="2.21058144654638E-05" />
    </inertial>
    <visual>
      <origin
        xyz="0 0 0"
        rpy="0 0 0" />
      <geometry>
        <mesh
          filename="package://lide/meshes/bcam.STL" />
      </geometry>
      <material
        name="">
        <color
          rgba="0.792156862745098 0.819607843137255 0.933333333333333 1" />
      </material>
    </visual>
    <collision>
      <origin
        xyz="0 0 0"
        rpy="0 0 0" />
      <geometry>
        <mesh
          filename="package://lide/meshes/bcam.STL" />
      </geometry>
    </collision>
  </link>
  <joint
    name="bcam"
    type="fixed">
    <origin
      xyz="0 0.083 0.091232"
      rpy="0 0.7854 0" />
    <parent
      link="base_link" />
    <child
      link="bcam" />
    <axis
      xyz="0 0 0" />
  </joint>
  <link
    name="Lidar">
    <inertial>
      <origin
        xyz="0.0135233595886408 0.000461955982206247 -0.028764885495051"
        rpy="0 0 0" />
      <mass
        value="0.0730845717569496" />
      <inertia
        ixx="1.95808757419765E-05"
        ixy="-1.03933585736234E-07"
        ixz="-4.28391168396099E-07"
        iyy="2.41250079666672E-05"
        iyz="9.42710206434147E-09"
        izz="4.14184516368183E-05" />
    </inertial>
    <visual>
      <origin
        xyz="0 0 0"
        rpy="0 0 0" />
      <geometry>
        <mesh
          filename="package://lide/meshes/Lidar.STL" />
      </geometry>
      <material
        name="">
        <color
          rgba="0.792156862745098 0.819607843137255 0.933333333333333 1" />
      </material>
    </visual>
    <collision>
      <origin
        xyz="0 0 0"
        rpy="0 0 0" />
      <geometry>
        <mesh
          filename="package://lide/meshes/Lidar.STL" />
      </geometry>
    </collision>
  </link>
  <joint
    name="Lidar"
    type="fixed">
    <origin
      xyz="-0.19458 0.082006 0.2065"
      rpy="0 0 0" />
    <parent
      link="base_link" />
    <child
      link="Lidar" />
    <axis
      xyz="0 0 0" />
  </joint>
  <link
    name="imu_link">
    <inertial>
      <origin
        xyz="0.00385022026093959 6.239840080563E-05 -0.00103377575234337"
        rpy="0 0 0" />
      <mass
        value="0.00189180567975737" />
      <inertia
        ixx="7.79431263454135E-08"
        ixy="1.39214190556514E-10"
        ixz="1.54511633252899E-11"
        iyy="4.85473464623125E-08"
        iyz="-6.30099051334897E-11"
        izz="1.25233585370532E-07" />
    </inertial>
    <visual>
      <origin
        xyz="0 0 0"
        rpy="0 0 0" />
      <geometry>
        <mesh
          filename="package://lide/meshes/imu_link.STL" />
      </geometry>
      <material
        name="">
        <color
          rgba="0.898039215686275 0.917647058823529 0.929411764705882 1" />
      </material>
    </visual>
    <collision>
      <origin
        xyz="0 0 0"
        rpy="0 0 0" />
      <geometry>
        <mesh
          filename="package://lide/meshes/imu_link.STL" />
      </geometry>
    </collision>
  </link>
  <joint
    name="imu_link"
    type="fixed">
    <origin
      xyz="-0.039 0.083 0.155"
      rpy="0 0 0" />
    <parent
      link="base_link" />
    <child
      link="imu_link" />
    <axis
      xyz="0 0 0" />
  </joint>
</robot>